Traceback (most recent call last):
  File "/Users/vivien/holberton school/holbertonschool-hbnb/part2/app/test_api.py", line 35, in test_get_user
    user_id = response.get_json()['id']
KeyError: 'id'

======================================================================
ERROR: test_update_user (app.test_api.TestUserEndpoints)
----------------------------------------------------------------------
Traceback (most recent call last):
  File "/Users/vivien/holberton school/holbertonschool-hbnb/part2/app/test_api.py", line 51, in test_update_user
    user_id = response.get_json()['id']
KeyError: 'id'

======================================================================
FAIL: test_create_user_with_existing_email (app.test_api.TestUserEndpoints)
----------------------------------------------------------------------
Traceback (most recent call last):
  File "/Users/vivien/holberton school/holbertonschool-hbnb/part2/app/test_api.py", line 90, in test_create_user_with_existing_email
    self.assertEqual(response.status_code, 201)
AssertionError: 400 != 201

======================================================================
FAIL: test_get_all_users_empty (app.test_api.TestUserEndpoints)
----------------------------------------------------------------------
Traceback (most recent call last):
  File "/Users/vivien/holberton school/holbertonschool-hbnb/part2/app/test_api.py", line 82, in test_get_all_users_empty
    self.assertIn('[]', response.get_data(as_text=True))
AssertionError: '[]' not found in '[\n    {\n        "id": "72234482-b173-4046-a81c-0422a2904b53",\n        "first_name": "Roger",\n        "last_name": "Rabbit",\n        "email": "roger.rabbit@example.com"\n    }\n]\n'

----------------------------------------------------------------------
Ran 9 tests in 0.049s

FAILED (failures=2, errors=2)
vivien@Mac part2 % python3 -m unittest app.test_api
..F.FE.E.
======================================================================
ERROR: test_get_user (app.test_api.TestUserEndpoints)
----------------------------------------------------------------------
Traceback (most recent call last):
  File "/Users/vivien/holberton school/holbertonschool-hbnb/part2/app/test_api.py", line 35, in test_get_user
    user_id = response.get_json()['id']
KeyError: 'id'

======================================================================
ERROR: test_update_user (app.test_api.TestUserEndpoints)
----------------------------------------------------------------------
Traceback (most recent call last):
  File "/Users/vivien/holberton school/holbertonschool-hbnb/part2/app/test_api.py", line 51, in test_update_user
    user_id = response.get_json()['id']
KeyError: 'id'

======================================================================
FAIL: test_create_user_with_existing_email (app.test_api.TestUserEndpoints)
----------------------------------------------------------------------
Traceback (most recent call last):
  File "/Users/vivien/holberton school/holbertonschool-hbnb/part2/app/test_api.py", line 90, in test_create_user_with_existing_email
    self.assertEqual(response.status_code, 201)
AssertionError: 400 != 201

======================================================================
FAIL: test_get_all_users_empty (app.test_api.TestUserEndpoints)
----------------------------------------------------------------------
Traceback (most recent call last):
  File "/Users/vivien/holberton school/holbertonschool-hbnb/part2/app/test_api.py", line 82, in test_get_all_users_empty
    self.assertIn('[]', response.get_data(as_text=True))
AssertionError: '[]' not found in '[\n    {\n        "id": "5575dfbb-687f-48fd-a869-9150fad5b4c5",\n        "first_name": "Roger",\n        "last_name": "Rabbit",\n        "email": "roger.rabbit@example.com"\n    }\n]\n'

----------------------------------------------------------------------
Ran 9 tests in 0.047s

FAILED (failures=2, errors=2)
vivien@Mac part2 % python3 -m unittest app.test_api
..F.FE.E.
======================================================================
ERROR: test_get_user (app.test_api.TestUserEndpoints)
----------------------------------------------------------------------
Traceback (most recent call last):
  File "/Users/vivien/holberton school/holbertonschool-hbnb/part2/app/test_api.py", line 35, in test_get_user
    user_id = response.get_json()['id']
KeyError: 'id'

======================================================================
ERROR: test_update_user (app.test_api.TestUserEndpoints)
----------------------------------------------------------------------
Traceback (most recent call last):
  File "/Users/vivien/holberton school/holbertonschool-hbnb/part2/app/test_api.py", line 51, in test_update_user
    user_id = response.get_json()['id']
KeyError: 'id'

======================================================================
FAIL: test_create_user_with_existing_email (app.test_api.TestUserEndpoints)
----------------------------------------------------------------------
Traceback (most recent call last):
  File "/Users/vivien/holberton school/holbertonschool-hbnb/part2/app/test_api.py", line 90, in test_create_user_with_existing_email
    self.assertEqual(response.status_code, 201)
AssertionError: 400 != 201

======================================================================
FAIL: test_get_all_users_empty (app.test_api.TestUserEndpoints)
----------------------------------------------------------------------
Traceback (most recent call last):
  File "/Users/vivien/holberton school/holbertonschool-hbnb/part2/app/test_api.py", line 82, in test_get_all_users_empty
    self.assertIn('[]', response.get_data(as_text=True))
AssertionError: '[]' not found in '[\n    {\n        "id": "a7144c30-a03a-442c-9105-c4cc846a3fa2",\n        "first_name": "Roger",\n        "last_name": "Rabbit",\n        "email": "roger.rabbit@example.com"\n    }\n]\n'

----------------------------------------------------------------------
Ran 9 tests in 0.046s

FAILED (failures=2, errors=2)
vivien@Mac part2 % python3 -m unittest app.test_api
..F.F....
======================================================================
FAIL: test_create_user_with_existing_email (app.test_api.TestUserEndpoints)
----------------------------------------------------------------------
Traceback (most recent call last):
  File "/Users/vivien/holberton school/holbertonschool-hbnb/part2/app/test_api.py", line 97, in test_create_user_with_existing_email
    self.assertEqual(response.status_code, 400)
AssertionError: 201 != 400

======================================================================
FAIL: test_get_all_users_empty (app.test_api.TestUserEndpoints)
----------------------------------------------------------------------
Traceback (most recent call last):
  File "/Users/vivien/holberton school/holbertonschool-hbnb/part2/app/test_api.py", line 82, in test_get_all_users_empty
    self.assertIn('[]', response.get_data(as_text=True))
AssertionError: '[]' not found in '[\n    {\n        "id": "8ff2a7e0-cf34-4efb-833b-e2e1441d59ed",\n        "first_name": "Roger",\n        "last_name": "Rabbit",\n        "email": "roger.rabbit@example.com"\n    }\n]\n'

----------------------------------------------------------------------
Ran 9 tests in 0.048s

FAILED (failures=2)
vivien@Mac part2 % python3 -m unittest app.test_api
..F.F....
======================================================================
FAIL: test_create_user_with_existing_email (app.test_api.TestUserEndpoints)
----------------------------------------------------------------------
Traceback (most recent call last):
  File "/Users/vivien/holberton school/holbertonschool-hbnb/part2/app/test_api.py", line 97, in test_create_user_with_existing_email
    self.assertEqual(response.status_code, 400)
AssertionError: 201 != 400

======================================================================
FAIL: test_get_all_users_empty (app.test_api.TestUserEndpoints)
----------------------------------------------------------------------
Traceback (most recent call last):
  File "/Users/vivien/holberton school/holbertonschool-hbnb/part2/app/test_api.py", line 82, in test_get_all_users_empty
    self.assertIn('[]', response.get_data(as_text=True))
AssertionError: '[]' not found in '[\n    {\n        "id": "75da7949-fffe-4288-9855-1baada8553f0",\n        "first_name": "Roger",\n        "last_name": "Rabbit",\n        "email": "roger.rabbit@example.com"\n    }\n]\n'

----------------------------------------------------------------------
Ran 9 tests in 0.048s

FAILED (failures=2)
vivien@Mac part2 % python3 -m unittest app.test_api
..F.F....
======================================================================
FAIL: test_create_user_with_existing_email (app.test_api.TestUserEndpoints)
----------------------------------------------------------------------
Traceback (most recent call last):
  File "/Users/vivien/holberton school/holbertonschool-hbnb/part2/app/test_api.py", line 97, in test_create_user_with_existing_email
    self.assertEqual(response.status_code, 400)
AssertionError: 201 != 400

======================================================================
FAIL: test_get_all_users_empty (app.test_api.TestUserEndpoints)
----------------------------------------------------------------------
Traceback (most recent call last):
  File "/Users/vivien/holberton school/holbertonschool-hbnb/part2/app/test_api.py", line 82, in test_get_all_users_empty
    self.assertIn('[]', response.get_data(as_text=True))
AssertionError: '[]' not found in '[\n    {\n        "id": "94a2799d-ef37-4917-a4bf-e55e13b1346a",\n        "first_name": "Roger",\n        "last_name": "Rabbit",\n        "email": "roger.rabbit@example.com"\n    }\n]\n'

----------------------------------------------------------------------
Ran 9 tests in 0.048s

FAILED (failures=2)
vivien@Mac part2 % python3 -m unittest app.test_api
F.FF.E.E.
======================================================================
ERROR: test_get_user (app.test_api.TestUserEndpoints)
----------------------------------------------------------------------
Traceback (most recent call last):
  File "/Users/vivien/holberton school/holbertonschool-hbnb/part2/app/test_api.py", line 35, in test_get_user
    user_id = response.get_json()['id']
KeyError: 'id'

======================================================================
ERROR: test_update_user (app.test_api.TestUserEndpoints)
----------------------------------------------------------------------
Traceback (most recent call last):
  File "/Users/vivien/holberton school/holbertonschool-hbnb/part2/app/test_api.py", line 51, in test_update_user
    user_id = response.get_json()['id']
KeyError: 'id'

======================================================================
FAIL: test_create_user (app.test_api.TestUserEndpoints)
----------------------------------------------------------------------
Traceback (most recent call last):
  File "/Users/vivien/holberton school/holbertonschool-hbnb/part2/app/test_api.py", line 19, in test_create_user
    self.assertEqual(response.status_code, 201)
AssertionError: 400 != 201

======================================================================
FAIL: test_create_user_with_existing_email (app.test_api.TestUserEndpoints)
----------------------------------------------------------------------
Traceback (most recent call last):
  File "/Users/vivien/holberton school/holbertonschool-hbnb/part2/app/test_api.py", line 90, in test_create_user_with_existing_email
    self.assertEqual(response.status_code, 201)
AssertionError: 400 != 201

======================================================================
FAIL: test_get_all_users (app.test_api.TestUserEndpoints)
----------------------------------------------------------------------
Traceback (most recent call last):
  File "/Users/vivien/holberton school/holbertonschool-hbnb/part2/app/test_api.py", line 77, in test_get_all_users
    self.assertIn('Roger', response.get_data(as_text=True))
AssertionError: 'Roger' not found in '[]\n'

----------------------------------------------------------------------
Ran 9 tests in 0.048s

FAILED (failures=3, errors=2)
vivien@Mac part2 % python3 -m unittest app.test_api
..F.F....
======================================================================
FAIL: test_create_user_with_existing_email (app.test_api.TestUserEndpoints)
----------------------------------------------------------------------
Traceback (most recent call last):
  File "/Users/vivien/holberton school/holbertonschool-hbnb/part2/app/test_api.py", line 97, in test_create_user_with_existing_email
    self.assertEqual(response.status_code, 400)
AssertionError: 201 != 400

======================================================================
FAIL: test_get_all_users_empty (app.test_api.TestUserEndpoints)
----------------------------------------------------------------------
Traceback (most recent call last):
  File "/Users/vivien/holberton school/holbertonschool-hbnb/part2/app/test_api.py", line 82, in test_get_all_users_empty
    self.assertIn('[]', response.get_data(as_text=True))
AssertionError: '[]' not found in '[\n    {\n        "id": "1a63d3b3-3a46-4f82-ac3b-f2004ca0bd9f",\n        "first_name": "Roger",\n        "last_name": "Rabbit",\n        "email": "roger.rabbit@example.com"\n    }\n]\n'

----------------------------------------------------------------------
Ran 9 tests in 0.048s
vivien@Mac part2 % python3 -m unittest app.test_api
..F....
======================================================================
FAIL: test_create_user_with_existing_email (app.test_api.TestUserEndpoints)
----------------------------------------------------------------------
Traceback (most recent call last):
  File "/Users/vivien/holberton school/holbertonschool-hbnb/part2/app/test_api.py", line 82, in test_create_user_with_existing_email
    self.assertEqual(response.status_code, 400)
AssertionError: 201 != 400

----------------------------------------------------------------------